Workbook

Sheet Instrucciones
B2: FASE 2 — BASE CONTABLE ANUAL · Matriz empresa–año–ratio
B3: Índice de resiliencia financiera sectorial · Empresas del S&P IPSA · 2017–2025
B5: Leyenda
B6: Celda de ingreso | C6: Datos a extraer de los estados financieros de la CMF. Texto azul sobre fondo amarillo.
B7: Celda calculada | C7: Fórmula automática. No modificar.
B8: Vínculo a otra hoja | C8: Fórmula que trae datos de otra hoja del libro (texto verde).
B9: Campo clave | C9: Empresa, sector y año. Ya vienen completados.
B11: Secuencia de trabajo
B12: Paso 1 | C12: Hoja «Empresas»: registre la moneda de presentación de cada sociedad (CLP o USD) y el precio ajustado de cierre al 31-12-2016, tomado de su archivo de precios de Yahoo Finance.
B13: Paso 2 | C13: Hojas «Captura_NoFin» y «Captura_Fin»: ingrese las partidas de los estados financieros consolidados anuales al 31 de diciembre, en miles de la moneda de presentación, tal como figuran en el documento de la CMF.
B14: Paso 3 | C14: Estrategia de extracción: cada estado financiero anual trae la columna del año y la comparativa del año anterior. Basta con abrir cinco documentos por empresa — ejercicios 2018, 2020, 2022, 2024 y 2025 — para cubrir los nueve años.
B15: Paso 4 | C15: Registre en la columna «fuente» el documento y la columna de donde tomó cada fila (p. ej. «EEFF 2020, comparativo»). Es la trazabilidad que declara su metodología.
B16: Paso 5 | C16: Hojas «Ratios_NoFin» y «Ratios_Fin»: se calculan solas. Revise la hoja «Control» antes de pasar a la Fase 3.
B18: Convenciones
B19: Signos | C19: Ingrese los costos financieros y el gasto en provisiones como números positivos. Las fórmulas usan su valor absoluto, de modo que un signo negativo tampoco produce error.
B20: Moneda | C20: No convierta a pesos. Todos los ratios son cocientes adimensionales y no cambian con la moneda. La conversión solo sería necesaria para variables de tamaño, que este diseño no utiliza.
B21: Sin dato | C21: Deje la celda vacía. Nunca ingrese cero para un dato faltante: un cero se calcula como valor real y sesga el ratio.
B22: EBIT | C22: Se calcula para todas las empresas como Ganancia antes de impuestos + Costos financieros. La columna «resultado operacional presentado» es solo informativa, porque NIC 1 no obliga a presentar ese subtotal.
B23: ROE | C23: Es descriptivo, no entra al KPI. Se deja en blanco cuando el patrimonio de la controladora es cero o negativo (caso Latam 2020–2021).
B24: Bancos | C24: Usan una plantilla propia y se ingresan en millones (MM$), tal como vienen. «Capital de trabajo» no aplica: sus estados no distinguen corriente de no corriente.
B26: Fila de ejemplo — formato esperado (valores ilustrativos, NO son datos reales de ninguna empresa)
B27: Campo | C27: Ejemplo | D27: Formato
B28: activo_corriente | C28: 845320 | D28: Miles de la moneda de presentación, sin puntos ni signo
B29: activo_total | C29: 4120550 | D29: Miles
B30: ingresos | C30: 1985400 | D30: Miles
B31: costos_financieros | C31: 62300 | D31: Positivo, en miles
B32: ganancia_antes_impuestos | C32: 210880 | D32: Puede ser negativo si hubo pérdida
B33: precio_ajustado_cierre | C33: 412,35 | D33: Precio ajustado por dividendos al último día hábil del año
B34: fuente | C34: EEFF 2020, comparativo | D34: Texto libre

Sheet Empresas
A1: N.º | B1: Nemotécnico | C1: Razón social | D1: Sector GICS | E1: Cód. sector | F1: Sector de análisis | G1: Plantilla | H1: Moneda de presentación | I1: Precio ajustado 31-12-2016 | J1: Observaciones
A2: 1 | B2: AGUAS-A | C2: Aguas Andinas S.A., Serie A | D2: Utilities | E2: 1 | F2: Servicios básicos e infraestructura | G2: No financiera | H2: CLP | I2: 191.32983
A3: 2 | B3: COLBUN | C3: Colbún S.A. | D3: Utilities | E3: 1 | F3: Servicios básicos e infraestructura | G3: No financiera | H3: USD | I3: 125.31001
A4: 3 | B4: ENELAM | C4: Enel Américas S.A. | D4: Utilities | E4: 1 | F4: Servicios básicos e infraestructura | G4: No financiera | H4: USD | I4: 104.2692 | J4: USD. Resultados por naturaleza (sin costo de ventas). 2024: ganancia extraordinaria por venta de activos en Perú.
A5: 4 | B5: ENELCHILE | C5: Enel Chile S.A. | D5: Utilities | E5: 1 | F5: Servicios básicos e infraestructura | G5: No financiera | I5: 38.458931
A6: 5 | B6: ECL | C6: Engie Energía Chile S.A. | D6: Utilities | E6: 1 | F6: Servicios básicos e infraestructura | G6: No financiera | H6: USD | I6: 1052.5234 | J6: USD (kUSD en los EEFF).
A7: 6 | B7: ENTEL | C7: Empresa Nacional de Telecomunicaciones S.A. | D7: Communication Services | E7: 1 | F7: Servicios básicos e infraestructura | G7: No financiera | H7: CLP | I7: 3329.6765
A8: 7 | B8: CENCOSUD | C8: Cencosud S.A. | D8: Consumer Staples (verificar) | E8: 2 | F8: Consumo | G8: No financiera | H8: CLP | I8: 1171.8052 | J8: Verificar sector GICS contra archivo de constituyentes de S&P DJI; no afecta la normalización.
A9: 8 | B9: FALABELLA | C9: Falabella S.A. | D9: Consumer Discretionary | E9: 2 | F9: Consumo | G9: No financiera | H9: CLP | I9: 4588.8062
A10: 9 | B10: RIPLEY | C10: Ripley Corp S.A. | D10: Consumer Discretionary | E10: 2 | F10: Consumo | G10: No financiera | H10: CLP | I10: 260.35175
A11: 10 | B11: CCU | C11: Compañía Cervecerías Unidas S.A. | D11: Consumer Staples | E11: 2 | F11: Consumo | G11: No financiera | H11: CLP | I11: 4615.2593
A12: 11 | B12: ANDINA-B | C12: Embotelladora Andina S.A., Serie B | D12: Consumer Staples | E12: 2 | F12: Consumo | G12: No financiera | H12: CLP | I12: 1467.3553
A13: 12 | B13: CONCHATORO | C13: Viña Concha y Toro S.A. | D13: Consumer Staples | E13: 2 | F13: Consumo | G13: No financiera | H13: CLP | I13: 789.89917
A14: 13 | B14: LTM | C14: Latam Airlines Group S.A. | D14: Industrials | E14: 3 | F14: Industria, recursos naturales e inmobiliario | G14: No financiera | H14: USD | I14: 313.14334 | J14: USD. ROE no disponible 2020–2021 por patrimonio negativo (reorganización Capítulo 11).
A15: 14 | B15: PARAUCO | C15: Parque Arauco S.A. | D15: Real Estate | E15: 3 | F15: Industria, recursos naturales e inmobiliario | G15: No financiera | H15: CLP | I15: 1274.4506 | J15: Propiedades de inversión a valor razonable (NIC 40): la utilidad puede incluir revalorizaciones.
A16: 15 | B16: CAP | C16: CAP S.A. | D16: Materials | E16: 3 | F16: Industria, recursos naturales e inmobiliario | G16: No financiera | H16: USD | I16: 2815.3384
A17: 16 | B17: CMPC | C17: Empresas CMPC S.A. | D17: Materials | E17: 3 | F17: Industria, recursos naturales e inmobiliario | G17: No financiera | H17: USD | I17: 1224.226
A18: 17 | B18: SQM-B | C18: Sociedad Química y Minera de Chile S.A., Serie B | D18: Materials | E18: 3 | F18: Industria, recursos naturales e inmobiliario | G18: No financiera | H18: USD | I18: 16181.312 | J18: USD. 2025: revisar perímetro por la sociedad NovaAndino Litio con Codelco.
A19: 18 | B19: COPEC | C19: Empresas Copec S.A. | D19: Energy | E19: 3 | F19: Industria, recursos naturales e inmobiliario | G19: No financiera | H19: USD | I19: 6182.0645
A20: 19 | B20: CHILE | C20: Banco de Chile | D20: Financials | E20: 4 | F20: Financiero (bancos) | G20: Financiera | H20: CLP | I20: 44.933334 | J20: Montos en MM$ (millones), tal como vienen del EEFF bancario.
A21: 20 | B21: BCI | C21: Banco de Crédito e Inversiones | D21: Financials | E21: 4 | F21: Financiero (bancos) | G21: Financiera | H21: CLP | I21: 15494.488 | J21: Montos en MM$ (millones), tal como vienen del EEFF bancario.
A22: 21 | B22: BSANTANDER | C22: Banco Santander-Chile | D22: Financials | E22: 4 | F22: Financiero (bancos) | G22: Financiera | H22: CLP | I22: 22.88047 | J22: Montos en MM$ (millones), tal como vienen del EEFF bancario.
A23: 22 | B23: ITAUCL | C23: Banco Itaú Chile | D23: Financials | E23: 4 | F23: Financiero (bancos) | G23: Financiera | H23: CLP | I23: 17342.992 | J23: Montos en MM$ (millones). Hasta 2021 figura como Itaú Corpbanca.
B25: Excluidas del panel:
B26: MALLPLAZA, SMU, CENCOMALLS — ingresaron al índice con posterioridad a 2017.
B27: IAM — salió en septiembre de 2018 y reingresó en septiembre de 2019.
B28: SALFACORP — salió en junio de 2020 y reingresó en septiembre de 2025.
B29: QUINENCO — registró una salida y reingresó en marzo de 2022.
B30: ILC — salió en septiembre de 2021 y reingresó en marzo de 2025.
B31: VAPORES — vehículo de inversión: la participación en Hapag-Lloyd concentra más del 92% de sus activos.
B32: Criterio: presencia ininterrumpida en el S&P IPSA 2017–2025 (anuncios de rebalanceo de S&P DJI).

Sheet Diccionario
A1: Código | B1: Campo | C1: Partida en los EEFF (CMF) | D1: Elemento taxonomía IFRS | E1: Estado financiero | F1: Condición | G1: Se usa en
A2: P01 | B2: activo_corriente | C2: Total de activos corrientes | D2: ifrs-full:CurrentAssets | E2: Situación financiera | F2: Núcleo | G2: Liquidez; Capital de trabajo
A3: P02 | B3: pasivo_corriente | C3: Total de pasivos corrientes | D3: ifrs-full:CurrentLiabilities | E3: Situación financiera | F3: Núcleo | G3: Liquidez; Capital de trabajo
A4: P03 | B4: activo_total | C4: Total de activos | D4: ifrs-full:Assets | E4: Situación financiera | F4: Núcleo | G4: Capital de trabajo; Rentabilidad; Endeudamiento; Uso de activos
A5: P04 | B5: pasivo_total | C5: Total de pasivos | D5: ifrs-full:Liabilities | E5: Situación financiera | F5: Núcleo | G5: Endeudamiento; control de cuadre
A6: P05 | B6: patrimonio_total | C6: Patrimonio total | D6: ifrs-full:Equity | E6: Situación financiera | F6: Núcleo | G6: Control de cuadre
A7: P06 | B7: ingresos | C7: Ingresos de actividades ordinarias | D7: ifrs-full:Revenue | E7: Resultados | F7: Núcleo | G7: Eficiencia; Uso de activos
A8: P07 | B8: costos_financieros | C8: Costos financieros | D8: ifrs-full:FinanceCosts | E8: Resultados | F8: Núcleo | G8: EBIT; Cobertura
A9: P08 | B9: ganancia_antes_impuestos | C9: Ganancia (pérdida), antes de impuestos | D9: ifrs-full:ProfitLossBeforeTax | E9: Resultados | F9: Núcleo | G9: EBIT
A10: P09 | B10: ganancia_ejercicio | C10: Ganancia (pérdida) | D10: ifrs-full:ProfitLoss | E10: Resultados | F10: Núcleo | G10: Rentabilidad (ROA)
A11: P10 | B11: patrimonio_controladora | C11: Patrimonio atribuible a los propietarios de la controladora | D11: ifrs-full:EquityAttributableToOwnersOfParent | E11: Situación financiera | F11: Opcional | G11: ROE descriptivo
A12: P11 | B12: ganancia_controladora | C12: Ganancia (pérdida), atribuible a los propietarios de la controladora | D12: ifrs-full:ProfitLossAttributableToOwnersOfParent | E12: Resultados | F12: Opcional | G12: ROE descriptivo
... A26: B11 | B26: ganancia_ejercicio | C26: UTILIDAD CONSOLIDADA DEL EJERCICIO | D26: Compendio CMF | E26: Resultados | F26: Núcleo | G26: Rentabilidad (ROA)
A28: P = empresas no financieras (18) · B = bancos (4) · M = dato de mercado, común a ambas. Bancos: montos en MM$, tal como vienen; no convertir.
A29: Bancos: el Compendio de Normas Contables de la CMF se actualizó con vigencia desde 2022. Homologue los rubros de 2021 usando la columna comparativa del EEFF 2022.

Sheet Captura_NoFin
A1: nemotecnico | B1: cod_sector | C1: sector | D1: anio | E1: moneda | F1: activo_corriente | G1: pasivo_corriente | H1: activo_total | I1: pasivo_total | J1: patrimonio_total | K1: ingresos | L1: costos_financieros | M1: ganancia_antes_impuestos | N1: ganancia_ejercicio | O1: patrimonio_controladora | P1: ganancia_controladora | Q1: resultado_operacional_presentado | R1: precio_ajustado_cierre | S1: fuente | T1: observaciones
A2: AGUAS-A | B2: 1 | C2: Servicios básicos e infraestructura | D2: 2017 | E2: =IFERROR(INDEX(Empresas!$H$2:$H$23,MATCH($A2,Empresas!$B$2:$B$23,0))&"","") | F2: 150618761 | G2: 237111903 | H2: 1796880136 | I2: 1103580659 | J2: 693299477 | K2: 509540577 | L2: 31112258 | M2: 189822878 | N2: 143482253 | O2: 642630776 | P2: 139620280 | Q2: 226819054 | R2: 236.90225 | S2: XBRL 2018, comparativo
A3: AGUAS-A | B3: 1 | C3: Servicios básicos e infraestructura | D3: 2018 | E3: =IFERROR(INDEX(Empresas!$H$2:$H$23,MATCH($A3,Empresas!$B$2:$B$23,0))&"","") | F3: 168513972 | G3: 242318524 | H3: 1906052099 | I3: 1219060702 | J3: 686991397 | K3: 530404680 | L3: 29996785 | M3: 185824777 | N3: 139318355 | O3: 638620655 | P3: 136056517 | Q3: 233071676 | R3: 234.73775 | S3: XBRL 2018, actual
A4: AGUAS-A | B4: 1 | C4: Servicios básicos e infraestructura | D4: 2019 | E4: =IFERROR(INDEX(Empresas!$H$2:$H$23,MATCH($A4,Empresas!$B$2:$B$23,0))&"","") | F4: 197676646 | G4: 242137717 | H4: 2001444302 | I4: 1313970839 | J4: 687473463 | K4: 484329084 | L4: 26752209 | M4: 192072838 | N4: 139750372 | O4: 644453334 | P4: 141737188 | Q4: 235636236 | R4: 207.44206 | S4: XBRL 2020, comparativo
A5: AGUAS-A | B5: 1 | C5: Servicios básicos e infraestructura | D5: 2020 | E5: =IFERROR(INDEX(Empresas!$H$2:$H$23,MATCH($A5,Empresas!$B$2:$B$23,0))&"","") | F5: 302254499 | G5: 244032589 | H5: 2144436488 | I5: 1303687681 | J5: 840748807 | K5: 478773563 | L5: 28172393 | M5: 115681631 | N5: 100365495 | O5: 840723242 | P5: 98691668 | Q5: 162824880 | R5: 159.16322 | S5: XBRL 2020, actual
A6: AGUAS-A | B6: 1 | C6: Servicios básicos e infraestructura | D6: 2021 | E6: =IFERROR(INDEX(Empresas!$H$2:$H$23,MATCH($A6,Empresas!$B$2:$B$23,0))&"","") | F6: 283854689 | G6: 248642211 | H6: 2229221610 | I6: 1386673897 | J6: 842547713 | K6: 506459633 | L6: 27862844 | M6: 120309420 | N6: 100646534 | O6: 842520215 | P6: 100644529 | Q6: 212947803 | R6: 118.44007 | S6: XBRL 2022, comparativo
A7: AGUAS-A | B7: 1 | C7: Servicios básicos e infraestructura | D7: 2022 | E7: =IFERROR(INDEX(Empresas!$H$2:$H$23,MATCH($A7,Empresas!$B$2:$B$23,0))&"","") | F7: 324838124 | G7: 265797147 | H7: 2379349560 | I7: 1540458461 | J7: 838891099 | K7: 575465445 | L7: 36630374 | M7: 82672491 | N7: 85250874 | O7: 838861526 | P7: 85248734 | Q7: 228258340 | R7: 160.16978 | S7: XBRL 2022, actual
A8: AGUAS-A | B8: 1 | C8: Servicios básicos e infraestructura | D8: 2023 | E8: =IFERROR(INDEX(Empresas!$H$2:$H$23,MATCH($A8,Empresas!$B$2:$B$23,0))&"","") | F8: 275004410 | G8: 361668126 | H8: 2423347729 | I8: 1537208431 | J8: 886139298 | K8: 640855854 | L8: 48849432 | M8: 167301553 | N8: 133392316 | O8: 886107830 | P8: 133390421 | Q8: 256251484 | R8: 246.37361 | S8: XBRL 2024, comparativo
A9: AGUAS-A | B9: 1 | C9: Servicios básicos e infraestructura | D9: 2024 | E9: =IFERROR(INDEX(Empresas!$H$2:$H$23,MATCH($A9,Empresas!$B$2:$B$23,0))&"","") | F9: 288702263 | G9: 351513489 | H9: 3018159335 | I9: 1726043867 | J9: 1292115468 | K9: 663124854 | L9: 49334397 | M9: 158648372 | N9: 124341654 | O9: 1292066950 | P9: 124339646 | Q9: 250689914 | R9: 273.23779 | S9: XBRL 2025, comparativo
A10: AGUAS-A | B10: 1 | C10: Servicios básicos e infraestructura | D10: 2025 | E10: =IFERROR(INDEX(Empresas!$H$2:$H$23,MATCH($A10,Empresas!$B$2:$B$23,0))&"","") | F10: 349120706 | G10: 279876332 | H10: 3160940487 | I10: 1837956795 | J10: 1322983692 | K10: 712787064 | L10: 55425087 | M10: 177385719 | N10: 139810947 | O10: 1322935141 | P10: 139808491 | Q10: 270051183 | R10: 358.47021 | S10: XBRL 2025, actual
A11: COLBUN | B11: 1 | C11: Servicios básicos e infraestructura | D11: 2017 | E11: =IFERROR(INDEX(Empresas!$H$2:$H$23,MATCH($A11,Empresas!$B$2:$B$23,0))&"","") | F11: 1147162 | G11: 360397 | H11: 6922542 | I11: 2971835 | J11: 3950707 | K11: 1548412 | L11: 84954 | M11: 322682 | N11: 288602 | O11: 3724532 | P11: 270985 | Q11: 383837 | R11: 140.41795 | S11: XBRL 2018, comparativo
A12: COLBUN | B12: 1 | C12: Servicios básicos e infraestructura | D12: 2018 | E12: =IFERROR(INDEX(Empresas!$H$2:$H$23,MATCH($A12,Empresas!$B$2:$B$23,0))&"","") | F12: 1151263 | G12: 345365 | H12: 6778349 | I12: 2921411 | J12: 3856938 | K12: 1571347 | L12: 83871 | M12: 328843 | N12: 230425 | O12: 3656514 | P12: 240350 | Q12: 393600 | R12: 138.35886 | S12: XBRL 2018, actual
A13: COLBUN | B13: 1 | C13: Servicios básicos e infraestructura | D13: 2019 | E13: =IFERROR(INDEX(Empresas!$H$2:$H$23,MATCH($A13,Empresas!$B$2:$B$23,0))&"","") | F13: 1139451 | G13: 338298 | H13: 6705350 | I13: 2969715 | J13: 3735635 | K13: 1487387 | L13: 91069 | M13: 270182 | N13: 201966 | O13: 3536293 | P13: 203047 | Q13: 337210 | R13: 119.15425 | S13: XBRL 2020, comparativo
... A28: ENELAM | B28: 1 | C28: Servicios básicos e infraestructura | D28: 2025 | E28: =IFERROR(INDEX(Empresas!$H$2:$H$23,MATCH($A28,Empresas!$B$2:$B$23,0))&"","") | F28: 6695824 | G28: 7737034 | H28: 34871081 | I28: 16294367 | J28: 18576714 | K28: 12818885 | L28: 1307207 | M28: 1902104 | N28: 1345692 | O28: 16023472 | P28: 960070 | Q28: 3051640 | R28: 85.657028 | S28: XBRL 2025, actual
A29: ENELCHILE | B29: 1 | C29: Servicios básicos e infraestructura | D29: 2017 | E29: =IFERROR(INDEX(Empresas!$H$2:$H$23,MATCH($A29,Empresas!$B$2:$B$23,0))&"","") | F29: 1055136552 | G29: 816816646 | H29: 5694773008 | I29: 1907811351 | J29: 3786961657 | K29: 2484101582 | L29: 53510882 | M29: 666760212 | N29: 523417911 | O29: 2983384010 | Q29: 691871770 | R29: 47.22459 | S29: XBRL 2018, comparativo
A30: ENELCHILE | B30: 1 | C30: Servicios básicos e infraestructura | D30: 2018 | E30: =IFERROR(INDEX(Empresas!$H$2:$H$23,MATCH($A30,Empresas!$B$2:$B$23,0))&"","") | F30: 996947772 | G30: 1217464152 | H30: 7488020164 | I30: 3813856383 | J30: 3674163781 | K30: 2410360459 | L30: 122184189 | M30: 566330276 | N30: 412847757 | O30: 3421228519 | Q30: 674015100 | R30: 45.228989 | S30: XBRL 2018, actual
A31: ENELCHILE | B31: 1 | C31: Servicios básicos e infraestructura | D31: 2019 | E31: =IFERROR(INDEX(Empresas!$H$2:$H$23,MATCH($A31,Empresas!$B$2:$B$23,0))&"","") | F31: 1018212660 | G31: 1041299852 | H31: 7857988164 | I31: 4110704512 | J31: 3747283652 | K31: 2624576323 | L31: 164897900 | M31: 377321122 | N31: 316093218 | O31: 3484697986 | P31: 296153605 | Q31: 537895036 | R31: 49.978222 | S31: XBRL 2020, comparativo
A32: ENELCHILE | B32: 1 | C32: Servicios básicos e infraestructura | D32: 2020 | E32: =IFERROR(INDEX(Empresas!$H$2:$H$23,MATCH($A32,Empresas!$B$2:$B$23,0))&"","") | F32: 1026401196 | G32: 1045480165 | H32: 7904471584 | I32: 4310197085 | J32: 3594274499 | K32: 2548384317 | L32: 127408771 | M32: -133691942 | N32: -52386835 | O32: 3351915790 | P32: -50860313 | Q32: -9598853 | R32: 41.88335 | S32: XBRL 2020, actual
A33: ENELCHILE | B33: 1 | C33: Servicios básicos e infraestructura | D33: 2021 | E33: =IFERROR(INDEX(Empresas!$H$2:$H$23,MATCH($A33,Empresas!$B$2:$B$23,0))&"","") | F33: 1268252493 | G33: 2132326217 | H33: 9500323596 | I33: 6153830698 | J33: 3346492898 | K33: 2829682404 | L33: 174043116 | M33: 115848792 | N33: 100710134 | O33: 3097868353 | P33: 85153969 | Q33: 288496122 | R33: 24.271528 | S33: XBRL 2022, comparativo
A34: ENELCHILE | B34: 1 | C34: Servicios básicos e infraestructura | D34: 2022 | E34: =IFERROR(INDEX(Empresas!$H$2:$H$23,MATCH($A34,Empresas!$B$2:$B$23,0))&"","") | F34: 3064242319 | G34: 3168491880 | H34: 11865579732 | I34: 7476640429 | J34: 4388939303 | K34: 4379000090 | L34: 193618033 | M34: 1778680669 | N34: 1308983789 | O34: 4097200895 | P34: 1252082258 | Q34: 1916363887 | R34: 32.246185 | S34: XBRL 2022, actual
A35: ENELCHILE | B35: 1 | C35: Servicios básicos e infraestructura | D35: 2023 | E35: =IFERROR(INDEX(Empresas!$H$2:$H$23,MATCH($A35,Empresas!$B$2:$B$23,0))&"","") | F35: 2370971259 | G35: 2793918344 | H35: 11833721036 | I35: 7072834764 | J35: 4760886272 | K35: 4262591097 | L35: 247067556 | M35: 906925876 | N35: 680013391 | O35: 4446079918 | P35: 633455775 | Q35: 1000381600 | R35: 47.549023 | S35: XBRL 2024, comparativo
A36: ENELCHILE | B36: 1 | C36: Servicios básicos e infraestructura | D36: 2024 | E36: =IFERROR(INDEX(Empresas!$H$2:$H$23,MATCH($A36,Empresas!$B$2:$B$23,0))&"","") | F36: 2242156 | G36: 2251458 | H36: 12765086 | I36: 7419784 | J36: 5345302 | K36: 4137511 | L36: 246450 | M36: 239443 | N36: 202432 | O36: 4976415 | P36: 153763 | Q36: 414518 | R36: 52.085506 | S36: XBRL 2025, comparativo
A37: ENELCHILE | B37: 1 | C37: Servicios básicos e infraestructura | D37: 2025 | E37: =IFERROR(INDEX(Empresas!$H$2:$H$23,MATCH($A37,Empresas!$B$2:$B$23,0))&"","") | F37: 2239087 | G37: 2473336 | H37: 12903659 | I37: 7354152 | J37: 5549507 | K37: 4509547 | L37: 330272 | M37: 794958 | N37: 584899 | O37: 5175869 | P37: 537629 | Q37: 1055798 | R37: 71.38958 | S37: XBRL 2025, actual
A38: ECL | B38: 1 | C38: Servicios básicos e infraestructura | D38: 2017 | E38: =IFERROR(INDEX(Empresas!$H$2:$H$23,MATCH($A38,Empresas!$B$2:$B$23,0))&"","") | F38: 381378 | G38: 333019 | H38: 3364203 | I38: 1298732 | J38: 2065471 | K38: 1054062 | L38: 11594 | M38: 143494 | N38: 109010 | O38: 1991493 | P38: 100862 | Q38: 148439 | R38: 1321.5504 | S38: XBRL 2018, comparativo
A39: ECL | B39: 1 | C39: Servicios básicos e infraestructura | D39: 2018 | E39: =IFERROR(INDEX(Empresas!$H$2:$H$23,MATCH($A39,Empresas!$B$2:$B$23,0))&"","") | F39: 427615 | G39: 305766 | H39: 3462736 | I39: 1324712 | J39: 2138024 | K39: 1275296 | L39: 12771 | M39: 149562 | N39: 111223 | O39: 2069806 | P39: 102582 | Q39: 151834 | R39: 1268.027 | S39: XBRL 2018, actual
A40: ECL | B40: 1 | C40: Servicios básicos e infraestructura | D40: 2019 | E40: =IFERROR(INDEX(Empresas!$H$2:$H$23,MATCH($A40,Empresas!$B$2:$B$23,0))&"","") | F40: 485255 | G40: 357485 | H40: 3507790 | I40: 1384189 | J40: 2123601 | K40: 1454436 | L40: 37837 | M40: 161321 | N40: 118717 | O40: 2059251 | P40: 110823 | Q40: 189682 | R40: 1144.675 | S40: XBRL 2020, comparativo
A41: ECL | B41: 1 | C41: Servicios básicos e infraestructura | D41: 2020 | E41: =IFERROR(INDEX(Empresas!$H$2:$H$23,MATCH($A41,Empresas!$B$2:$B$23,0))&"","") | F41: 464866 | G41: 323459 | H41: 3720980 | I41: 1552972 | J41: 2168008 | K41: 1351658 | L41: 59476 | M41: 203722 | N41: 163531 | O41: 2168008 | P41: 163531 | Q41: 263554 | R41: 869.81396 | S41: XBRL 2020, actual
A42: ECL | B42: 1 | C42: Servicios básicos e infraestructura | D42: 2021 | E42: =IFERROR(INDEX(Empresas!$H$2:$H$23,MATCH($A42,Empresas!$B$2:$B$23,0))&"","") | F42: 616232 | G42: 397389 | H42: 3998862 | I42: 1826851 | J42: 2172011 | K42: 1478614 | L42: 88807 | M42: 60797 | N42: 47374 | O42: 2172011 | P42: 47374 | Q42: 127339 | R42: 501.96219 | S42: XBRL 2022, comparativo
... A48: ENTEL | B48: 1 | C48: Servicios básicos e infraestructura | D48: 2018 | E48: =IFERROR(INDEX(Empresas!$H$2:$H$23,MATCH($A48,Empresas!$B$2:$B$23,0))&"","") | F48: 810596112 | G48: 658742932 | H48: 3964215271 | I48: 2597793309 | J48: 1366421962 | K48: 1913174282 | L48: 77711185 | M48: -2270976 | N48: -23614092 | O48: 1366421962 | P48: -23614092 | Q48: 90913071 | R48: 2549.1682 | S48: XBRL 2018, actual
A49: ENTEL | B49: 1 | C49: Servicios básicos e infraestructura | D49: 2019 | E49: =IFERROR(INDEX(Empresas!$H$2:$H$23,MATCH($A49,Empresas!$B$2:$B$23,0))&"","") | F49: 1350183140 | G49: 891001450 | H49: 5169493602 | I49: 3560819204 | J49: 1608674398 | K49: 1978791988 | L49: 97558997 | M49: 240209837 | N49: 154152106 | O49: 1608674398 | Q49: 343916569 | R49: 2533.2522 | S49: XBRL 2020, comparativo
A50: ENTEL | B50: 1 | C50: Servicios básicos e infraestructura | D50: 2020 | E50: =IFERROR(INDEX(Empresas!$H$2:$H$23,MATCH($A50,Empresas!$B$2:$B$23,0))&"","") | F50: 1376958931 | G50: 814156775 | H50: 4888444532 | I50: 3379954105 | J50: 1508490427 | K50: 2092644232 | L50: 102535938 | M50: 93954056 | N50: 84466248 | O50: 1508490427 | Q50: 212469036 | R50: 2153.9814 | S50: XBRL 2020, actual
A51: ENTEL | B51: 1 | C51: Servicios básicos e infraestructura | D51: 2021 | E51: =IFERROR(INDEX(Empresas!$H$2:$H$23,MATCH($A51,Empresas!$B$2:$B$23,0))&"","") | F51: 1295049133 | G51: 1157171716 | H51: 5470958637 | I51: 3967913270 | J51: 1503045367 | K51: 2408809597 | L51: 113951133 | M51: 118630360 | N51: 74975311 | O51: 1503045367 | P51: 74975311 | Q51: 294374685 | R51: 1837.4656 | S51: XBRL 2022, comparativo
A52: ENTEL | B52: 1 | C52: Servicios básicos e infraestructura | D52: 2022 | E52: =IFERROR(INDEX(Empresas!$H$2:$H$23,MATCH($A52,Empresas!$B$2:$B$23,0))&"","") | F52: 1484646595 | G52: 1132020070 | H52: 5595346439 | I52: 4040830663 | J52: 1554515776 | K52: 2540682904 | L52: 113696383 | M52: 539751444 | N52: 456787332 | O52: 1554515776 | P52: 456787332 | Q52: 757608676 | R52: 2344.2937 | S52: XBRL 2022, actual
A53: ENTEL | B53: 1 | C53: Servicios básicos e infraestructura | D53: 2023 | E53: =IFERROR(INDEX(Empresas!$H$2:$H$23,MATCH($A53,Empresas!$B$2:$B$23,0))&"","") | F53: 1596064579 | G53: 1336992696 | H53: 5698687722 | I53: 4023234762 | J53: 1675452960 | K53: 2473692310 | L53: 113270200 | M53: 120594631 | N53: 88884366 | O53: 1675452960 | P53: 88884366 | Q53: 249569340 | R53: 2655.2822 | S53: XBRL 2024, comparativo
A54: ENTEL | B54: 1 | C54: Servicios básicos e infraestructura | D54: 2024 | E54: =IFERROR(INDEX(Empresas!$H$2:$H$23,MATCH($A54,Empresas!$B$2:$B$23,0))&"","") | F54: 1354153503 | G54: 1390644381 | H54: 5839398906 | I54: 4003379269 | J54: 1836019637 | K54: 2703236728 | L54: 111986497 | M54: 131167257 | N54: 67672129 | O54: 1836019637 | P54: 67672129 | Q54: 230852594 | R54: 2653.1975 | S54: XBRL 2025, comparativo
A55: ENTEL | B55: 1 | C55: Servicios básicos e infraestructura | D55: 2025 | E55: =IFERROR(INDEX(Empresas!$H$2:$H$23,MATCH($A55,Empresas!$B$2:$B$23,0))&"","") | F55: 1349902280 | G55: 1165931045 | H55: 5716879713 | I55: 3773582832 | J55: 1943296881 | K55: 2954930278 | L55: 165362521 | M55: 89153460 | N55: 191396469 | O55: 1943296881 | P55: 191396469 | Q55: 249853484 | R55: 4522.3081 | S55: XBRL 2025, actual
A56: CENCOSUD | B56: 2 | C56: Consumo | D56: 2017 | E56: =IFERROR(INDEX(Empresas!$H$2:$H$23,MATCH($A56,Empresas!$B$2:$B$23,0))&"","") | F56: 2616704742 | G56: 2695719238 | H56: 10024711422 | I56: 6015689973 | J56: 4009021449 | K56: 10456987206 | L56: 297173197 | M56: 638419975 | N56: 440135976 | O56: 4010150786 | P56: 439988718 | Q56: 825410527 | R56: 1181.6542 | S56: XBRL 2018, comparativo
A57: CENCOSUD | B57: 2 | C57: Consumo | D57: 2018 | E57: =IFERROR(INDEX(Empresas!$H$2:$H$23,MATCH($A57,Empresas!$B$2:$B$23,0))&"","") | F57: 2649598319 | G57: 2622878167 | H57: 10634698845 | I57: 6390656921 | J57: 4244041924 | K57: 9646001747 | L57: 237011354 | M57: 278346717 | N57: 190594477 | O57: 4245504837 | P57: 191285239 | Q57: 608906016 | R57: 840.58185 | S57: XBRL 2018, actual
A58: CENCOSUD | B58: 2 | C58: Consumo | D58: 2019 | E58: =IFERROR(INDEX(Empresas!$H$2:$H$23,MATCH($A58,Empresas!$B$2:$B$23,0))&"","") | F58: 3211830302 | G58: 2537199479 | H58: 12248307991 | I58: 7258386384 | J58: 4989921607 | K58: 9548213456 | L58: 282095846 | M58: 329464815 | N58: 154617183 | O58: 4442538398 | P58: 114109633 | Q58: 713608184 | R58: 667.63141 | S58: XBRL 2020, comparativo
A59: CENCOSUD | B59: 2 | C59: Consumo | D59: 2020 | E59: =IFERROR(INDEX(Empresas!$H$2:$H$23,MATCH($A59,Empresas!$B$2:$B$23,0))&"","") | F59: 2750870198 | G59: 2523502528 | H59: 10845080030 | I59: 6326579185 | J59: 4518500845 | K59: 9836117393 | L59: 264941294 | M59: 202558250 | N59: 64980678 | O59: 3957334556 | P59: 22930607 | Q59: 593715165 | R59: 879.85071 | S59: XBRL 2020, actual
...

Sheet Captura_Fin
A1: nemotecnico | B1: cod_sector | C1: sector | D1: anio | E1: moneda | F1: activo_total | G1: pasivo_total | H1: patrimonio_total | I1: efectivo | J1: depositos | K1: colocaciones | L1: ingreso_operacional_neto | M1: gastos_operacionales | N1: gasto_provisiones | O1: ganancia_antes_impuestos | P1: ganancia_ejercicio | Q1: precio_ajustado_cierre | R1: fuente | S1: observaciones
A2: CHILE | B2: 4 | C2: Financiero (bancos) | D2: 2017 | E2: =IFERROR(INDEX(Empresas!$H$2:$H$23,MATCH($A2,Empresas!$B$2:$B$23,0))&"","") | F2: 32824188 | G2: 29718473 | H2: 3105715 | I2: 1057393 | J2: 18983484 | K2: 24881353 | L2: 1709270 | M2: -789298 | N2: -234982 | O2: 691047 | P2: 576013 | Q2: 60.088425 | R2: CMF, estados mensuales 12/2017, MM$
A3: CHILE | B3: 4 | C3: Financiero (bancos) | D3: 2018 | E3: =IFERROR(INDEX(Empresas!$H$2:$H$23,MATCH($A3,Empresas!$B$2:$B$23,0))&"","") | F3: 35926459 | G3: 32622306 | H3: 3304153 | I3: 880081 | J3: 20240662 | K3: 27307223 | L3: 1873283 | M3: -847724 | N3: -281410 | O3: 751404 | P3: 594873 | Q3: 65.215981 | R3: CMF, estados mensuales 12/2018, MM$
A4: CHILE | B4: 4 | C4: Financiero (bancos) | D4: 2019 | E4: =IFERROR(INDEX(Empresas!$H$2:$H$23,MATCH($A4,Empresas!$B$2:$B$23,0))&"","") | F4: 41273333 | G4: 37745110 | H4: 3528223 | I4: 2392166 | J4: 22182751 | K4: 29334052 | L4: 2014520 | M4: -911004 | N4: -347274 | O4: 762692 | P4: 593009 | Q4: 54.254173 | R4: CMF, estados mensuales 12/2019, MM$
A5: CHILE | B5: 4 | C5: Financiero (bancos) | D5: 2020 | E5: =IFERROR(INDEX(Empresas!$H$2:$H$23,MATCH($A5,Empresas!$B$2:$B$23,0))&"","") | F5: 46095131 | G5: 42368863 | H5: 3726268 | I5: 2560216 | J5: 24066770 | K5: 30190058 | L5: 1938743 | M5: -882331 | N5: -462680 | O5: 589071 | P5: 463109 | Q5: 51.982399 | R5: CMF, estados mensuales 12/2020, MM$
A6: CHILE | B6: 4 | C6: Financiero (bancos) | D6: 2021 | E6: =IFERROR(INDEX(Empresas!$H$2:$H$23,MATCH($A6,Empresas!$B$2:$B$23,0))&"","") | F6: 51702439 | G6: 47479425 | H6: 4223014 | I6: 3713734 | J6: 27682797 | K6: 33537758 | L6: 2230257 | M6: -887764 | N6: -373260 | O6: 971473 | P6: 792923 | Q6: 48.897358 | R6: CMF, estados mensuales 12/2021, MM$
A7: CHILE | B7: 4 | C7: Financiero (bancos) | D7: 2022 | E7: =IFERROR(INDEX(Empresas!$H$2:$H$23,MATCH($A7,Empresas!$B$2:$B$23,0))&"","") | F7: 55255362 | G7: 50397034 | H7: 4858327.9 | I7: 2764883.9 | J7: 27540373 | K7: 35916413 | L7: 3115792.3 | M7: -995483.41 | N7: -435117.02 | O7: 1685191.9 | P7: 1409435.3 | Q7: 68.847427 | R7: CMF, estados mensuales 12/2022, MM$
A8: CHILE | B8: 4 | C8: Financiero (bancos) | D8: 2023 | E8: =IFERROR(INDEX(Empresas!$H$2:$H$23,MATCH($A8,Empresas!$B$2:$B$23,0))&"","") | F8: 55792552 | G8: 50555267 | H8: 5237284.7 | I8: 2464647.7 | J8: 28687222 | K8: 36831736 | L8: 2997278.2 | M8: -1118503.9 | N8: -361252.1 | O8: 1517522.1 | P8: 1243634.8 | Q8: 90.303284 | R8: CMF, estados mensuales 12/2023, MM$
A9: CHILE | B9: 4 | C9: Financiero (bancos) | D9: 2024 | E9: =IFERROR(INDEX(Empresas!$H$2:$H$23,MATCH($A9,Empresas!$B$2:$B$23,0))&"","") | F9: 52095442 | G9: 46472440 | H9: 5623001.4 | I9: 2699076.1 | J9: 28432005 | K9: 38089036 | L9: 3050285.2 | M9: -1132734.1 | N9: -391753.97 | O9: 1525797.1 | P9: 1207391.7 | Q9: 98.645157 | R9: CMF, estados mensuales 12/2024, MM$
A10: CHILE | B10: 4 | C10: Financiero (bancos) | D10: 2025 | E10: =IFERROR(INDEX(Empresas!$H$2:$H$23,MATCH($A10,Empresas!$B$2:$B$23,0))&"","") | F10: 54100904 | G10: 48301368 | H10: 5799536.2 | I10: 2590986.3 | J10: 28470164 | K10: 38354999 | L10: 3026042.7 | M10: -1130937.5 | N10: -381922.56 | O10: 1513182.7 | P10: 1192261.6 | Q10: 164.06694 | R10: CMF, estados mensuales 12/2025, MM$
A11: BCI | B11: 4 | C11: Financiero (bancos) | D11: 2017 | E11: =IFERROR(INDEX(Empresas!$H$2:$H$23,MATCH($A11,Empresas!$B$2:$B$23,0))&"","") | F11: 33883396 | G11: 31155110 | H11: 2728286 | I11: 1495732 | J11: 20226470 | K11: 24130419 | L11: 1380702 | M11: -741612 | N11: -212653 | O11: 538979 | P11: 371425 | Q11: 20320.629 | R11: CMF, estados mensuales 12/2017, MM$
A12: BCI | B12: 4 | C12: Financiero (bancos) | D12: 2018 | E12: =IFERROR(INDEX(Empresas!$H$2:$H$23,MATCH($A12,Empresas!$B$2:$B$23,0))&"","") | F12: 41349717 | G12: 37891354 | H12: 3458363 | I12: 2058757 | J12: 24551315 | K12: 29543095 | L12: 1585203 | M12: -864277 | N12: -266313 | O12: 519649 | P12: 395847 | Q12: 22217.955 | R12: CMF, estados mensuales 12/2018, MM$
A13: BCI | B13: 4 | C13: Financiero (bancos) | D13: 2019 | E13: =IFERROR(INDEX(Empresas!$H$2:$H$23,MATCH($A13,Empresas!$B$2:$B$23,0))&"","") | F13: 50336620 | G13: 46544100 | H13: 3792520 | I13: 3153760 | J13: 27553455 | K13: 33212457 | L13: 1891788 | M13: -957731 | N13: -415519 | O13: 531176 | P13: 402739 | Q13: 17913.963 | R13: CMF, estados mensuales 12/2019, MM$
... A37: ITAUCL | B37: 4 | C37: Financiero (bancos) | D37: 2025 | E37: =IFERROR(INDEX(Empresas!$H$2:$H$23,MATCH($A37,Empresas!$B$2:$B$23,0))&"","") | F37: 43916278 | G37: 39607525 | H37: 4308752.7 | I37: 2892660.3 | J37: 21456814 | K37: 28119106 | L37: 1518133 | M37: -834788.8 | N37: -319328.39 | O37: 364015.81 | P37: 428108.53 | Q37: 18837.979 | R37: CMF, estados mensuales 12/2025, MM$

Sheet Ratios_NoFin
A1: nemotecnico | B1: cod_sector | C1: sector | D1: anio | E1: EBIT | F1: F1_liquidez | G1: F2_capital_trabajo | H1: F3_eficiencia | I1: F4_rentabilidad_ROA | J1: F5_endeudamiento | K1: F6_cobertura | L1: F7_uso_activos | M1: F8_mercado_retorno | N1: ROE_descriptivo | O1: familias_validas | P1: cuadre_contable
A2: =Captura_NoFin!A2 | B2: =Captura_NoFin!B2 | C2: =Captura_NoFin!C2 | D2: =Captura_NoFin!D2 | E2: =IF(COUNT(Captura_NoFin!M2,Captura_NoFin!L2)<2,"",Captura_NoFin!M2+ABS(Captura_NoFin!L2)) | F2: =IF(COUNT(Captura_NoFin!F2,Captura_NoFin!G2)<2,"",IFERROR(Captura_NoFin!F2/Captura_NoFin!G2,"")) | G2: =IF(COUNT(Captura_NoFin!F2,Captura_NoFin!G2,Captura_NoFin!H2)<3,"",IFERROR((Captura_NoFin!F2-Captura_NoFin!G2)/Captura_NoFin!H2,"")) | H2: =IF(OR(E2="",COUNT(Captura_NoFin!K2)<1),"",IFERROR(E2/Captura_NoFin!K2,"")) | I2: =IF(COUNT(Captura_NoFin!N2,Captura_NoFin!H2)<2,"",IFERROR(Captura_NoFin!N2/Captura_NoFin!H2,"")) | J2: =IF(COUNT(Captura_NoFin!I2,Captura_NoFin!H2)<2,"",IFERROR(Captura_NoFin!I2/Captura_NoFin!H2,"")) | K2: =IF(OR(E2="",COUNT(Captura_NoFin!L2)<1),"",IFERROR(E2/ABS(Captura_NoFin!L2),"")) | L2: =IF(COUNT(Captura_NoFin!K2,Captura_NoFin!H2)<2,"",IFERROR(Captura_NoFin!K2/Captura_NoFin!H2,"")) | M2: =IF(COUNT(Captura_NoFin!R2)<1,"",IFERROR(IF(D2=2017,Captura_NoFin!R2/INDEX(Empresas!$I$2:$I$23,MATCH($A2,Empresas!$B$2:$B$23,0))-1,IF(COUNT(Captura_NoFin!R1)<1,"",Captura_NoFin!R2/Captura_NoFin!R1-1)),"")) | N2: =IF(COUNT(Captura_NoFin!P2,Captura_NoFin!O2)<2,"",IF(Captura_NoFin!O2<=0,"",Captura_NoFin!P2/Captura_NoFin!O2)) | O2: =COUNT(F2:M2) | P2: =IF(COUNT(Captura_NoFin!H2,Captura_NoFin!I2,Captura_NoFin!J2)<3,"",IF(ABS(Captura_NoFin!H2-Captura_NoFin!I2-Captura_NoFin!J2)<=0.005*ABS(Captura_NoFin!H2),"OK","REVISAR"))
A3: =Captura_NoFin!A3 | B3: =Captura_NoFin!B3 | C3: =Captura_NoFin!C3 | D3: =Captura_NoFin!D3 | E3: =IF(COUNT(Captura_NoFin!M3,Captura_NoFin!L3)<2,"",Captura_NoFin!M3+ABS(Captura_NoFin!L3)) | F3: =IF(COUNT(Captura_NoFin!F3,Captura_NoFin!G3)<2,"",IFERROR(Captura_NoFin!F3/Captura_NoFin!G3,"")) | G3: =IF(COUNT(Captura_NoFin!F3,Captura_NoFin!G3,Captura_NoFin!H3)<3,"",IFERROR((Captura_NoFin!F3-Captura_NoFin!G3)/Captura_NoFin!H3,"")) | H3: =IF(OR(E3="",COUNT(Captura_NoFin!K3)<1),"",IFERROR(E3/Captura_NoFin!K3,"")) | I3: =IF(COUNT(Captura_NoFin!N3,Captura_NoFin!H3)<2,"",IFERROR(Captura_NoFin!N3/Captura_NoFin!H3,"")) | J3: =IF(COUNT(Captura_NoFin!I3,Captura_NoFin!H3)<2,"",IFERROR(Captura_NoFin!I3/Captura_NoFin!H3,"")) | K3: =IF(OR(E3="",COUNT(Captura_NoFin!L3)<1),"",IFERROR(E3/ABS(Captura_NoFin!L3),"")) | L3: =IF(COUNT(Captura_NoFin!K3,Captura_NoFin!H3)<2,"",IFERROR(Captura_NoFin!K3/Captura_NoFin!H3,"")) | M3: =IF(COUNT(Captura_NoFin!R3)<1,"",IFERROR(IF(D3=2017,Captura_NoFin!R3/INDEX(Empresas!$I$2:$I$23,MATCH($A3,Empresas!$B$2:$B$23,0))-1,IF(COUNT(Captura_NoFin!R2)<1,"",Captura_NoFin!R3/Captura_NoFin!R2-1)),"")) | N3: =IF(COUNT(Captura_NoFin!P3,Captura_NoFin!O3)<2,"",IF(Captura_NoFin!O3<=0,"",Captura_NoFin!P3/Captura_NoFin!O3)) | O3: =COUNT(F3:M3) | P3: =IF(COUNT(Captura_NoFin!H3,Captura_NoFin!I3,Captura_NoFin!J3)<3,"",IF(ABS(Captura_NoFin!H3-Captura_NoFin!I3-Captura_NoFin!J3)<=0.005*ABS(Captura_NoFin!H3),"OK","REVISAR"))
A4: =Captura_NoFin!A4 | B4: =Captura_NoFin!B4 | C4: =Captura_NoFin!C4 | D4: =Captura_NoFin!D4 | E4: =IF(COUNT(Captura_NoFin!M4,Captura_NoFin!L4)<2,"",Captura_NoFin!M4+ABS(Captura_NoFin!L4)) | F4: =IF(COUNT(Captura_NoFin!F4,Captura_NoFin!G4)<2,"",IFERROR(Captura_NoFin!F4/Captura_NoFin!G4,"")) | G4: =IF(COUNT(Captura_NoFin!F4,Captura_NoFin!G4,Captura_NoFin!H4)<3,"",IFERROR((Captura_NoFin!F4-Captura_NoFin!G4)/Captura_NoFin!H4,"")) | H4: =IF(OR(E4="",COUNT(Captura_NoFin!K4)<1),"",IFERROR(E4/Captura_NoFin!K4,"")) | I4: =IF(COUNT(Captura_NoFin!N4,Captura_NoFin!H4)<2,"",IFERROR(Captura_NoFin!N4/Captura_NoFin!H4,"")) | J4: =IF(COUNT(Captura_NoFin!I4,Captura_NoFin!H4)<2,"",IFERROR(Captura_NoFin!I4/Captura_NoFin!H4,"")) | K4: =IF(OR(E4="",COUNT(Captura_NoFin!L4)<1),"",IFERROR(E4/ABS(Captura_NoFin!L4),"")) | L4: =IF(COUNT(Captura_NoFin!K4,Captura_NoFin!H4)<2,"",IFERROR(Captura_NoFin!K4/Captura_NoFin!H4,"")) | M4: =IF(COUNT(Captura_NoFin!R4)<1,"",IFERROR(IF(D4=2017,Captura_NoFin!R4/INDEX(Empresas!$I$2:$I$23,MATCH($A4,Empresas!$B$2:$B$23,0))-1,IF(COUNT(Captura_NoFin!R3)<1,"",Captura_NoFin!R4/Captura_NoFin!R3-1)),"")) | N4: =IF(COUNT(Captura_NoFin!P4,Captura_NoFin!O4)<2,"",IF(Captura_NoFin!O4<=0,"",Captura_NoFin!P4/Captura_NoFin!O4)) | O4: =COUNT(F4:M4) | P4: =IF(COUNT(Captura_NoFin!H4,Captura_NoFin!I4,Captura_NoFin!J4)<3,"",IF(ABS(Captura_NoFin!H4-Captura_NoFin!I4-Captura_NoFin!J4)<=0.005*ABS(Captura_NoFin!H4),"OK","REVISAR"))
A5: =Captura_NoFin!A5 | B5: =Captura_NoFin!B5 | C5: =Captura_NoFin!C5 | D5: =Captura_NoFin!D5 | E5: =IF(COUNT(Captura_NoFin!M5,Captura_NoFin!L5)<2,"",Captura_NoFin!M5+ABS(Captura_NoFin!L5)) | F5: =IF(COUNT(Captura_NoFin!F5,Captura_NoFin!G5)<2,"",IFERROR(Captura_NoFin!F5/Captura_NoFin!G5,"")) | G5: =IF(COUNT(Captura_NoFin!F5,Captura_NoFin!G5,Captura_NoFin!H5)<3,"",IFERROR((Captura_NoFin!F5-Captura_NoFin!G5)/Captura_NoFin!H5,"")) | H5: =IF(OR(E5="",COUNT(Captura_NoFin!K5)<1),"",IFERROR(E5/Captura_NoFin!K5,"")) | I5: =IF(COUNT(Captura_NoFin!N5,Captura_NoFin!H5)<2,"",IFERROR(Captura_NoFin!N5/Captura_NoFin!H5,"")) | J5: =IF(COUNT(Captura_NoFin!I5,Captura_NoFin!H5)<2,"",IFERROR(Captura_NoFin!I5/Captura_NoFin!H5,"")) | K5: =IF(OR(E5="",COUNT(Captura_NoFin!L5)<1),"",IFERROR(E5/ABS(Captura_NoFin!L5),"")) | L5: =IF(COUNT(Captura_NoFin!K5,Captura_NoFin!H5)<2,"",IFERROR(Captura_NoFin!K5/Captura_NoFin!H5,"")) | M5: =IF(COUNT(Captura_NoFin!R5)<1,"",IFERROR(IF(D5=2017,Captura_NoFin!R5/INDEX(Empresas!$I$2:$I$23,MATCH($A5,Empresas!$B$2:$B$23,0))-1,IF(COUNT(Captura_NoFin!R4)<1,"",Captura_NoFin!R5/Captura_NoFin!R4-1)),"")) | N5: =IF(COUNT(Captura_NoFin!P5,Captura_NoFin!O5)<2,"",IF(Captura_NoFin!O5<=0,"",Captura_NoFin!P5/Captura_NoFin!O5)) | O5: =COUNT(F5:M5) | P5: =IF(COUNT(Captura_NoFin!H5,Captura_NoFin!I5,Captura_NoFin!J5)<3,"",IF(ABS(Captura_NoFin!H5-Captura_NoFin!I5-Captura_NoFin!J5)<=0.005*ABS(Captura_NoFin!H5),"OK","REVISAR"))
A6: =Captura_NoFin!A6 | B6: =Captura_NoFin!B6 | C6: =Captura_NoFin!C6 | D6: =Captura_NoFin!D6 | E6: =IF(COUNT(Captura_NoFin!M6,Captura_NoFin!L6)<2,"",Captura_NoFin!M6+ABS(Captura_NoFin!L6)) | F6: =IF(COUNT(Captura_NoFin!F6,Captura_NoFin!G6)<2,"",IFERROR(Captura_NoFin!F6/Captura_NoFin!G6,"")) | G6: =IF(COUNT(Captura_NoFin!F6,Captura_NoFin!G6,Captura_NoFin!H6)<3,"",IFERROR((Captura_NoFin!F6-Captura_NoFin!G6)/Captura_NoFin!H6,"")) | H6: =IF(OR(E6="",COUNT(Captura_NoFin!K6)<1),"",IFERROR(E6/Captura_NoFin!K6,"")) | I6: =IF(COUNT(Captura_NoFin!N6,Captura_NoFin!H6)<2,"",IFERROR(Captura_NoFin!N6/Captura_NoFin!H6,"")) | J6: =IF(COUNT(Captura_NoFin!I6,Captura_NoFin!H6)<2,"",IFERROR(Captura_NoFin!I6/Captura_NoFin!H6,"")) | K6: =IF(OR(E6="",COUNT(Captura_NoFin!L6)<1),"",IFERROR(E6/ABS(Captura_NoFin!L6),"")) | L6: =IF(COUNT(Captura_NoFin!K6,Captura_NoFin!H6)<2,"",IFERROR(Captura_NoFin!K6/Captura_NoFin!H6,"")) | M6: =IF(COUNT(Captura_NoFin!R6)<1,"",IFERROR(IF(D6=2017,Captura_NoFin!R6/INDEX(Empresas!$I$2:$I$23,MATCH($A6,Empresas!$B$2:$B$23,0))-1,IF(COUNT(Captura_NoFin!R5)<1,"",Captura_NoFin!R6/Captura_NoFin!R5-1)),"")) | N6: =IF(COUNT(Captura_NoFin!P6,Captura_NoFin!O6)<2,"",IF(Captura_NoFin!O6<=0,"",Captura_NoFin!P6/Captura_NoFin!O6)) | O6: =COUNT(F6:M6) | P6: =IF(COUNT(Captura_NoFin!H6,Captura_NoFin!I6,Captura_NoFin!J6)<3,"",IF(ABS(Captura_NoFin!H6-Captura_NoFin!I6-Captura_NoFin!J6)<=0.005*ABS(Captura_NoFin!H6),"OK","REVISAR"))
A7: =Captura_NoFin!A7 | B7: =Captura_NoFin!B7 | C7: =Captura_NoFin!C7 | D7: =Captura_NoFin!D7 | E7: =IF(COUNT(Captura_NoFin!M7,Captura_NoFin!L7)<2,"",Captura_NoFin!M7+ABS(Captura_NoFin!L7)) | F7: =IF(COUNT(Captura_NoFin!F7,Captura_NoFin!G7)<2,"",IFERROR(Captura_NoFin!F7/Captura_NoFin!G7,"")) | G7: =IF(COUNT(Captura_NoFin!F7,Captura_NoFin!G7,Captura_NoFin!H7)<3,"",IFERROR((Captura_NoFin!F7-Captura_NoFin!G7)/Captura_NoFin!H7,"")) | H7: =IF(OR(E7="",COUNT(Captura_NoFin!K7)<1),"",IFERROR(E7/Captura_NoFin!K7,"")) | I7: =IF(COUNT(Captura_NoFin!N7,Captura_NoFin!H7)<2,"",IFERROR(Captura_NoFin!N7/Captura_NoFin!H7,"")) | J7: =IF(COUNT(Captura_NoFin!I7,Captura_NoFin!H7)<2,"",IFERROR(Captura_NoFin!I7/Captura_NoFin!H7,"")) | K7: =IF(OR(E7="",COUNT(Captura_NoFin!L7)<1),"",IFERROR(E7/ABS(Captura_NoFin!L7),"")) | L7: =IF(COUNT(Captura_NoFin!K7,Captura_NoFin!H7)<2,"",IFERROR(Captura_NoFin!K7/Captura_NoFin!H7,"")) | M7: =IF(COUNT(Captura_NoFin!R7)<1,"",IFERROR(IF(D7=2017,Captura_NoFin!R7/INDEX(Empresas!$I$2:$I$23,MATCH($A7,Empresas!$B$2:$B$23,0))-1,IF(COUNT(Captura_NoFin!R6)<1,"",Captura_NoFin!R7/Captura_NoFin!R6-1)),"")) | N7: =IF(COUNT(Captura_NoFin!P7,Captura_NoFin!O7)<2,"",IF(Captura_NoFin!O7<=0,"",Captura_NoFin!P7/Captura_NoFin!O7)) | O7: =COUNT(F7:M7) | P7: =IF(COUNT(Captura_NoFin!H7,Captura_NoFin!I7,Captura_NoFin!J7)<3,"",IF(ABS(Captura_NoFin!H7-Captura_NoFin!I7-Captura_NoFin!J7)<=0.005*ABS(Captura_NoFin!H7),"OK","REVISAR"))
A8: =Captura_NoFin!A8 | B8: =Captura_NoFin!B8 | C8: =Captura_NoFin!C8 | D8: =Captura_NoFin!D8 | E8: =IF(COUNT(Captura_NoFin!M8,Captura_NoFin!L8)<2,"",Captura_NoFin!M8+ABS(Captura_NoFin!L8)) | F8: =IF(COUNT(Captura_NoFin!F8,Captura_NoFin!G8)<2,"",IFERROR(Captura_NoFin!F8/Captura_NoFin!G8,"")) | G8: =IF(COUNT(Captura_NoFin!F8,Captura_NoFin!G8,Captura_NoFin!H8)<3,"",IFERROR((Captura_NoFin!F8-Captura_NoFin!G8)/Captura_NoFin!H8,"")) | H8: =IF(OR(E8="",COUNT(Captura_NoFin!K8)<1),"",IFERROR(E8/Captura_NoFin!K8,"")) | I8: =IF(COUNT(Captura_NoFin!N8,Captura_NoFin!H8)<2,"",IFERROR(Captura_NoFin!N8/Captura_NoFin!H8,"")) | J8: =IF(COUNT(Captura_NoFin!I8,Captura_NoFin!H8)<2,"",IFERROR(Captura_NoFin!I8/Captura_NoFin!H8,"")) | K8: =IF(OR(E8="",COUNT(Captura_NoFin!L8)<1),"",IFERROR(E8/ABS(Captura_NoFin!L8),"")) | L8: =IF(COUNT(Captura_NoFin!K8,Captura_NoFin!H8)<2,"",IFERROR(Captura_NoFin!K8/Captura_NoFin!H8,"")) | M8: =IF(COUNT(Captura_NoFin!R8)<1,"",IFERROR(IF(D8=2017,Captura_NoFin!R8/INDEX(Empresas!$I$2:$I$23,MATCH($A8,Empresas!$B$2:$B$23,0))-1,IF(COUNT(Captura_NoFin!R7)<1,"",Captura_NoFin!R8/Captura_NoFin!R7-1)),"")) | N8: =IF(COUNT(Captura_NoFin!P8,Captura_NoFin!O8)<2,"",IF(Captura_NoFin!O8<=0,"",Captura_NoFin!P8/Captura_NoFin!O8)) | O8: =COUNT(F8:M8) | P8: =IF(COUNT(Captura_NoFin!H8,Captura_NoFin!I8,Captura_NoFin!J8)<3,"",IF(ABS(Captura_NoFin!H8-Captura_NoFin!I8-Captura_NoFin!J8)<=0.005*ABS(Captura_NoFin!H8),"OK","REVISAR"))
A9: =Captura_NoFin!A9 | B9: =Captura_NoFin!B9 | C9: =Captura_NoFin!C9 | D9: =Captura_NoFin!D9 | E9: =IF(COUNT(Captura_NoFin!M9,Captura_NoFin!L9)<2,"",Captura_NoFin!M9+ABS(Captura_NoFin!L9)) | F9: =IF(COUNT(Captura_NoFin!F9,Captura_NoFin!G9)<2,"",IFERROR(Captura_NoFin!F9/Captura_NoFin!G9,"")) | G9: =IF(COUNT(Captura_NoFin!F9,Captura_NoFin!G9,Captura_NoFin!H9)<3,"",IFERROR((Captura_NoFin!F9-Captura_NoFin!G9)/Captura_NoFin!H9,"")) | H9: =IF(OR(E9="",COUNT(Captura_NoFin!K9)<1),"",IFERROR(E9/Captura_NoFin!K9,"")) | I9: =IF(COUNT(Captura_NoFin!N9,Captura_NoFin!H9)<2,"",IFERROR(Captura_NoFin!N9/Captura_NoFin!H9,"")) | J9: =IF(COUNT(Captura_NoFin!I9,Captura_NoFin!H9)<2,"",IFERROR(Captura_NoFin!I9/Captura_NoFin!H9,"")) | K9: =IF(OR(E9="",COUNT(Captura_NoFin!L9)<1),"",IFERROR(E9/ABS(Captura_NoFin!L9),"")) | L9: =IF(COUNT(Captura_NoFin!K9,Captura_NoFin!H9)<2,"",IFERROR(Captura_NoFin!K9/Captura_NoFin!H9,"")) | M9: =IF(COUNT(Captura_NoFin!R9)<1,"",IFERROR(IF(D9=2017,Captura_NoFin!R9/INDEX(Empresas!$I$2:$I$23,MATCH($A9,Empresas!$B$2:$B$23,0))-1,IF(COUNT(Captura_NoFin!R8)<1,"",Captura_NoFin!R9/Captura_NoFin!R8-1)),"")) | N9: =IF(COUNT(Captura_NoFin!P9,Captura_NoFin!O9)<2,"",IF(Captura_NoFin!O9<=0,"",Captura_NoFin!P9/Captura_NoFin!O9)) | O9: =COUNT(F9:M9) | P9: =IF(COUNT(Captura_NoFin!H9,Captura_NoFin!I9,Captura_NoFin!J9)<3,"",IF(ABS(Captura_NoFin!H9-Captura_NoFin!I9-Captura_NoFin!J9)<=0.005*ABS(Captura_NoFin!H9),"OK","REVISAR"))
A10: =Captura_NoFin!A10 | B10: =Captura_NoFin!B10 | C10: =Captura_NoFin!C10 | D10: =Captura_NoFin!D10 | E10: =IF(COUNT(Captura_NoFin!M10,Captura_NoFin!L10)<2,"",Captura_NoFin!M10+ABS(Captura_NoFin!L10)) | F10: =IF(COUNT(Captura_NoFin!F10,Captura_NoFin!G10)<2,"",IFERROR(Captura_NoFin!F10/Captura_NoFin!G10,"")) | G10: =IF(COUNT(Captura_NoFin!F10,Captura_NoFin!G10,Captura_NoFin!H10)<3,"",IFERROR((Captura_NoFin!F10-Captura_NoFin!G10)/Captura_NoFin!H10,"")) | H10: =IF(OR(E10="",COUNT(Captura_NoFin!K10)<1),"",IFERROR(E10/Captura_NoFin!K10,"")) | I10: =IF(COUNT(Captura_NoFin!N10,Captura_NoFin!H10)<2,"",IFERROR(Captura_NoFin!N10/Captura_NoFin!H10,"")) | J10: =IF(COUNT(Captura_NoFin!I10,Captura_NoFin!H10)<2,"",IFERROR(Captura_NoFin!I10/Captura_NoFin!H10,"")) | K10: =IF(OR(E10="",COUNT(Captura_NoFin!L10)<1),"",IFERROR(E10/ABS(Captura_NoFin!L10),"")) | L10: =IF(COUNT(Captura_NoFin!K10,Captura_NoFin!H10)<2,"",IFERROR(Captura_NoFin!K10/Captura_NoFin!H10,"")) | M10: =IF(COUNT(Captura_NoFin!R10)<1,"",IFERROR(IF(D10=2017,Captura_NoFin!R10/INDEX(Empresas!$I$2:$I$23,MATCH($A10,Empresas!$B$2:$B$23,0))-1,IF(COUNT(Captura_NoFin!R9)<1,"",Captura_NoFin!R10/Captura_NoFin!R9-1)),"")) | N10: =IF(COUNT(Captura_NoFin!P10,Captura_NoFin!O10)<2,"",IF(Captura_NoFin!O10<=0,"",Captura_NoFin!P10/Captura_NoFin!O10)) | O10: =COUNT(F10:M10) | P10: =IF(COUNT(Captura_NoFin!H10,Captura_NoFin!I10,Captura_NoFin!J10)<3,"",IF(ABS(Captura_NoFin!H10-Captura_NoFin!I10-Captura_NoFin!J10)<=0.005*ABS(Captura_NoFin!H10),"OK","REVISAR"))
A11: =Captura_NoFin!A11 | B11: =Captura_NoFin!B11 | C11: =Captura_NoFin!C11 | D11: =Captura_NoFin!D11 | E11: =IF(COUNT(Captura_NoFin!M11,Captura_NoFin!L11)<2,"",Captura_NoFin!M11+ABS(Captura_NoFin!L11)) | F11: =IF(COUNT(Captura_NoFin!F11,Captura_NoFin!G11)<2,"",IFERROR(Captura_NoFin!F11/Captura_NoFin!G11,"")) | G11: =IF(COUNT(Captura_NoFin!F11,Captura_NoFin!G11,Captura_NoFin!H11)<3,"",IFERROR((Captura_NoFin!F11-Captura_NoFin!G11)/Captura_NoFin!H11,"")) | H11: =IF(OR(E11="",COUNT(Captura_NoFin!K11)<1),"",IFERROR(E11/Captura_NoFin!K11,"")) | I11: =IF(COUNT(Captura_NoFin!N11,Captura_NoFin!H11)<2,"",IFERROR(Captura_NoFin!N11/Captura_NoFin!H11,"")) | J11: =IF(COUNT(Captura_NoFin!I11,Captura_NoFin!H11)<2,"",IFERROR(Captura_NoFin!I11/Captura_NoFin!H11,"")) | K11: =IF(OR(E11="",COUNT(Captura_NoFin!L11)<1),"",IFERROR(E11/ABS(Captura_NoFin!L11),"")) | L11: =IF(COUNT(Captura_NoFin!K11,Captura_NoFin!H11)<2,"",IFERROR(Captura_NoFin!K11/Captura_NoFin!H11,"")) | M11: =IF(COUNT(Captura_NoFin!R11)<1,"",IFERROR(IF(D11=2017,Captura_NoFin!R11/INDEX(Empresas!$I$2:$I$23,MATCH($A11,Empresas!$B$2:$B$23,0))-1,IF(COUNT(Captura_NoFin!R10)<1,"",Captura_NoFin!R11/Captura_NoFin!R10-1)),"")) | N11: =IF(COUNT(Captura_NoFin!P11,Captura_NoFin!O11)<2,"",IF(Captura_NoFin!O11<=0,"",Captura_NoFin!P11/Captura_NoFin!O11)) | O11: =COUNT(F11:M11) | P11: =IF(COUNT(Captura_NoFin!H11,Captura_NoFin!I11,Captura_NoFin!J11)<3,"",IF(ABS(Captura_NoFin!H11-Captura_NoFin!I11-Captura_NoFin!J11)<=0.005*ABS(Captura_NoFin!H11),"OK","REVISAR"))
A12: =Captura_NoFin!A12 | B12: =Captura_NoFin!B12 | C12: =Captura_NoFin!C12 | D12: =Captura_NoFin!D12 | E12: =IF(COUNT(Captura_NoFin!M12,Captura_NoFin!L12)<2,"",Captura_NoFin!M12+ABS(Captura_NoFin!L12)) | F12: =IF(COUNT(Captura_NoFin!F12,Captura_NoFin!G12)<2,"",IFERROR(Captura_NoFin!F12/Captura_NoFin!G12,"")) | G12: =IF(COUNT(Captura_NoFin!F12,Captura_NoFin!G12,Captura_NoFin!H12)<3,"",IFERROR((Captura_NoFin!F12-Captura_NoFin!G12)/Captura_NoFin!H12,"")) | H12: =IF(OR(E12="",COUNT(Captura_NoFin!K12)<1),"",IFERROR(E12/Captura_NoFin!K12,"")) | I12: =IF(COUNT(Captura_NoFin!N12,Captura_NoFin!H12)<2,"",IFERROR(Captura_NoFin!N12/Captura_NoFin!H12,"")) | J12: =IF(COUNT(Captura_NoFin!I12,Captura_NoFin!H12)<2,"",IFERROR(Captura_NoFin!I12/Captura_NoFin!H12,"")) | K12: =IF(OR(E12="",COUNT(Captura_NoFin!L12)<1),"",IFERROR(E12/ABS(Captura_NoFin!L12),"")) | L12: =IF(COUNT(Captura_NoFin!K12,Captura_NoFin!H12)<2,"",IFERROR(Captura_NoFin!K12/Captura_NoFin!H12,"")) | M12: =IF(COUNT(Captura_NoFin!R12)<1,"",IFERROR(IF(D12=2017,Captura_NoFin!R12/INDEX(Empresas!$I$2:$I$23,MATCH($A12,Empresas!$B$2:$B$23,0))-1,IF(COUNT(Captura_NoFin!R11)<1,"",Captura_NoFin!R12/Captura_NoFin!R11-1)),"")) | N12: =IF(COUNT(Captura_NoFin!P12,Captura_NoFin!O12)<2,"",IF(Captura_NoFin!O12<=0,"",Captura_NoFin!P12/Captura_NoFin!O12)) | O12: =COUNT(F12:M12) | P12: =IF(COUNT(Captura_NoFin!H12,Captura_NoFin!I12,Captura_NoFin!J12)<3,"",IF(ABS(Captura_NoFin!H12-Captura_NoFin!I12-Captura_NoFin!J12)<=0.005*ABS(Captura_NoFin!H12),"OK","REVISAR"))
A13: =Captura_NoFin!A13 | B13: =Captura_NoFin!B13 | C13: =Captura_NoFin!C13 | D13: =Captura_NoFin!D13 | E13: =IF(COUNT(Captura_NoFin!M13,Captura_NoFin!L13)<2,"",Captura_NoFin!M13+ABS(Captura_NoFin!L13)) | F13: =IF(COUNT(Captura_NoFin!F13,Captura_NoFin!G13)<2,"",IFERROR(Captura_NoFin!F13/Captura_NoFin!G13,"")) | G13: =IF(COUNT(Captura_NoFin!F13,Captura_NoFin!G13,Captura_NoFin!H13)<3,"",IFERROR((Captura_NoFin!F13-Captura_NoFin!G13)/Captura_NoFin!H13,"")) | H13: =IF(OR(E13="",COUNT(Captura_NoFin!K13)<1),"",IFERROR(E13/Captura_NoFin!K13,"")) | I13: =IF(COUNT(Captura_NoFin!N13,Captura_NoFin!H13)<2,"",IFERROR(Captura_NoFin!N13/Captura_NoFin!H13,"")) | J13: =IF(COUNT(Captura_NoFin!I13,Captura_NoFin!H13)<2,"",IFERROR(Captura_NoFin!I13/Captura_NoFin!H13,"")) | K13: =IF(OR(E13="",COUNT(Captura_NoFin!L13)<1),"",IFERROR(E13/ABS(Captura_NoFin!L13),"")) | L13: =IF(COUNT(Captura_NoFin!K13,Captura_NoFin!H13)<2,"",IFERROR(Captura_NoFin!K13/Captura_NoFin!H13,"")) | M13: =IF(COUNT(Captura_NoFin!R13)<1,"",IFERROR(IF(D13=2017,Captura_NoFin!R13/INDEX(Empresas!$I$2:$I$23,MATCH($A13,Empresas!$B$2:$B$23,0))-1,IF(COUNT(Captura_NoFin!R12)<1,"",Captura_NoFin!R13/Captura_NoFin!R12-1)),"")) | N13: =IF(COUNT(Captura_NoFin!P13,Captura_NoFin!O13)<2,"",IF(Captura_NoFin!O13<=0,"",Captura_NoFin!P13/Captura_NoFin!O13)) | O13: =COUNT(F13:M13) | P13: =IF(COUNT(Captura_NoFin!H13,Captura_NoFin!I13,Captura_NoFin!J13)<3,"",IF(ABS(Captura_NoFin!H13-Captura_NoFin!I13-Captura_NoFin!J13)<=0.005*ABS(Captura_NoFin!H13),"OK","REVISAR"))
... A163: =Captura_NoFin!A163 | B163: =Captura_NoFin!B163 | C163: =Captura_NoFin!C163 | D163: =Captura_NoFin!D163 | E163: =IF(COUNT(Captura_NoFin!M163,Captura_NoFin!L163)<2,"",Captura_NoFin!M163+ABS(Captura_NoFin!L163)) | F163: =IF(COUNT(Captura_NoFin!F163,Captura_NoFin!G163)<2,"",IFERROR(Captura_NoFin!F163/Captura_NoFin!G163,"")) | G163: =IF(COUNT(Captura_NoFin!F163,Captura_NoFin!G163,Captura_NoFin!H163)<3,"",IFERROR((Captura_NoFin!F163-Captura_NoFin!G163)/Captura_NoFin!H163,"")) | H163: =IF(OR(E163="",COUNT(Captura_NoFin!K163)<1),"",IFERROR(E163/Captura_NoFin!K163,"")) | I163: =IF(COUNT(Captura_NoFin!N163,Captura_NoFin!H163)<2,"",IFERROR(Captura_NoFin!N163/Captura_NoFin!H163,"")) | J163: =IF(COUNT(Captura_NoFin!I163,Captura_NoFin!H163)<2,"",IFERROR(Captura_NoFin!I163/Captura_NoFin!H163,"")) | K163: =IF(OR(E163="",COUNT(Captura_NoFin!L163)<1),"",IFERROR(E163/ABS(Captura_NoFin!L163),"")) | L163: =IF(COUNT(Captura_NoFin!K163,Captura_NoFin!H163)<2,"",IFERROR(Captura_NoFin!K163/Captura_NoFin!H163,"")) | M163: =IF(COUNT(Captura_NoFin!R163)<1,"",IFERROR(IF(D163=2017,Captura_NoFin!R163/INDEX(Empresas!$I$2:$I$23,MATCH($A163,Empresas!$B$2:$B$23,0))-1,IF(COUNT(Captura_NoFin!R162)<1,"",Captura_NoFin!R163/Captura_NoFin!R162-1)),"")) | N163: =IF(COUNT(Captura_NoFin!P163,Captura_NoFin!O163)<2,"",IF(Captura_NoFin!O163<=0,"",Captura_NoFin!P163/Captura_NoFin!O163)) | O163: =COUNT(F163:M163) | P163: =IF(COUNT(Captura_NoFin!H163,Captura_NoFin!I163,Captura_NoFin!J163)<3,"",IF(ABS(Captura_NoFin!H163-Captura_NoFin!I163-Captura_NoFin!J163)<=0.005*ABS(Captura_NoFin!H163),"OK","REVISAR"))

Sheet Ratios_Fin
A1: nemotecnico | B1: cod_sector | C1: sector | D1: anio | E1: F1_liquidez | F1: F3_eficiencia | G1: F4_rentabilidad_ROA | H1: F5_endeudamiento | I1: F6_cobertura | J1: F7_uso_activos | K1: F8_mercado_retorno | L1: ROE_descriptivo | M1: familias_validas | N1: cuadre_contable
A2: =Captura_Fin!A2 | B2: =Captura_Fin!B2 | C2: =Captura_Fin!C2 | D2: =Captura_Fin!D2 | E2: =IF(COUNT(Captura_Fin!I2,Captura_Fin!J2)<2,"",IFERROR(Captura_Fin!I2/Captura_Fin!J2,"")) | F2: =IF(COUNT(Captura_Fin!M2,Captura_Fin!L2)<2,"",IFERROR(ABS(Captura_Fin!M2)/Captura_Fin!L2,"")) | G2: =IF(COUNT(Captura_Fin!P2,Captura_Fin!F2)<2,"",IFERROR(Captura_Fin!P2/Captura_Fin!F2,"")) | H2: =IF(COUNT(Captura_Fin!G2,Captura_Fin!F2)<2,"",IFERROR(Captura_Fin!G2/Captura_Fin!F2,"")) | I2: =IF(COUNT(Captura_Fin!O2,Captura_Fin!N2)<2,"",IFERROR((Captura_Fin!O2+ABS(Captura_Fin!N2))/ABS(Captura_Fin!N2),"")) | J2: =IF(COUNT(Captura_Fin!L2,Captura_Fin!F2)<2,"",IFERROR(Captura_Fin!L2/Captura_Fin!F2,"")) | K2: =IF(COUNT(Captura_Fin!Q2)<1,"",IFERROR(IF(D2=2017,Captura_Fin!Q2/INDEX(Empresas!$I$2:$I$23,MATCH($A2,Empresas!$B$2:$B$23,0))-1,IF(COUNT(Captura_Fin!Q1)<1,"",Captura_Fin!Q2/Captura_Fin!Q1-1)),"")) | L2: =IF(COUNT(Captura_Fin!P2,Captura_Fin!H2)<2,"",IF(Captura_Fin!H2<=0,"",Captura_Fin!P2/Captura_Fin!H2)) | M2: =COUNT(E2:K2) | N2: =IF(COUNT(Captura_Fin!F2,Captura_Fin!G2,Captura_Fin!H2)<3,"",IF(ABS(Captura_Fin!F2-Captura_Fin!G2-Captura_Fin!H2)<=0.005*ABS(Captura_Fin!F2),"OK","REVISAR"))
A3: =Captura_Fin!A3 | B3: =Captura_Fin!B3 | C3: =Captura_Fin!C3 | D3: =Captura_Fin!D3 | E3: =IF(COUNT(Captura_Fin!I3,Captura_Fin!J3)<2,"",IFERROR(Captura_Fin!I3/Captura_Fin!J3,"")) | F3: =IF(COUNT(Captura_Fin!M3,Captura_Fin!L3)<2,"",IFERROR(ABS(Captura_Fin!M3)/Captura_Fin!L3,"")) | G3: =IF(COUNT(Captura_Fin!P3,Captura_Fin!F3)<2,"",IFERROR(Captura_Fin!P3/Captura_Fin!F3,"")) | H3: =IF(COUNT(Captura_Fin!G3,Captura_Fin!F3)<2,"",IFERROR(Captura_Fin!G3/Captura_Fin!F3,"")) | I3: =IF(COUNT(Captura_Fin!O3,Captura_Fin!N3)<2,"",IFERROR((Captura_Fin!O3+ABS(Captura_Fin!N3))/ABS(Captura_Fin!N3),"")) | J3: =IF(COUNT(Captura_Fin!L3,Captura_Fin!F3)<2,"",IFERROR(Captura_Fin!L3/Captura_Fin!F3,"")) | K3: =IF(COUNT(Captura_Fin!Q3)<1,"",IFERROR(IF(D3=2017,Captura_Fin!Q3/INDEX(Empresas!$I$2:$I$23,MATCH($A3,Empresas!$B$2:$B$23,0))-1,IF(COUNT(Captura_Fin!Q2)<1,"",Captura_Fin!Q3/Captura_Fin!Q2-1)),"")) | L3: =IF(COUNT(Captura_Fin!P3,Captura_Fin!H3)<2,"",IF(Captura_Fin!H3<=0,"",Captura_Fin!P3/Captura_Fin!H3)) | M3: =COUNT(E3:K3) | N3: =IF(COUNT(Captura_Fin!F3,Captura_Fin!G3,Captura_Fin!H3)<3,"",IF(ABS(Captura_Fin!F3-Captura_Fin!G3-Captura_Fin!H3)<=0.005*ABS(Captura_Fin!F3),"OK","REVISAR"))
A4: =Captura_Fin!A4 | B4: =Captura_Fin!B4 | C4: =Captura_Fin!C4 | D4: =Captura_Fin!D4 | E4: =IF(COUNT(Captura_Fin!I4,Captura_Fin!J4)<2,"",IFERROR(Captura_Fin!I4/Captura_Fin!J4,"")) | F4: =IF(COUNT(Captura_Fin!M4,Captura_Fin!L4)<2,"",IFERROR(ABS(Captura_Fin!M4)/Captura_Fin!L4,"")) | G4: =IF(COUNT(Captura_Fin!P4,Captura_Fin!F4)<2,"",IFERROR(Captura_Fin!P4/Captura_Fin!F4,"")) | H4: =IF(COUNT(Captura_Fin!G4,Captura_Fin!F4)<2,"",IFERROR(Captura_Fin!G4/Captura_Fin!F4,"")) | I4: =IF(COUNT(Captura_Fin!O4,Captura_Fin!N4)<2,"",IFERROR((Captura_Fin!O4+ABS(Captura_Fin!N4))/ABS(Captura_Fin!N4),"")) | J4: =IF(COUNT(Captura_Fin!L4,Captura_Fin!F4)<2,"",IFERROR(Captura_Fin!L4/Captura_Fin!F4,"")) | K4: =IF(COUNT(Captura_Fin!Q4)<1,"",IFERROR(IF(D4=2017,Captura_Fin!Q4/INDEX(Empresas!$I$2:$I$23,MATCH($A4,Empresas!$B$2:$B$23,0))-1,IF(COUNT(Captura_Fin!Q3)<1,"",Captura_Fin!Q4/Captura_Fin!Q3-1)),"")) | L4: =IF(COUNT(Captura_Fin!P4,Captura_Fin!H4)<2,"",IF(Captura_Fin!H4<=0,"",Captura_Fin!P4/Captura_Fin!H4)) | M4: =COUNT(E4:K4) | N4: =IF(COUNT(Captura_Fin!F4,Captura_Fin!G4,Captura_Fin!H4)<3,"",IF(ABS(Captura_Fin!F4-Captura_Fin!G4-Captura_Fin!H4)<=0.005*ABS(Captura_Fin!F4),"OK","REVISAR"))
A5: =Captura_Fin!A5 | B5: =Captura_Fin!B5 | C5: =Captura_Fin!C5 | D5: =Captura_Fin!D5 | E5: =IF(COUNT(Captura_Fin!I5,Captura_Fin!J5)<2,"",IFERROR(Captura_Fin!I5/Captura_Fin!J5,"")) | F5: =IF(COUNT(Captura_Fin!M5,Captura_Fin!L5)<2,"",IFERROR(ABS(Captura_Fin!M5)/Captura_Fin!L5,"")) | G5: =IF(COUNT(Captura_Fin!P5,Captura_Fin!F5)<2,"",IFERROR(Captura_Fin!P5/Captura_Fin!F5,"")) | H5: =IF(COUNT(Captura_Fin!G5,Captura_Fin!F5)<2,"",IFERROR(Captura_Fin!G5/Captura_Fin!F5,"")) | I5: =IF(COUNT(Captura_Fin!O5,Captura_Fin!N5)<2,"",IFERROR((Captura_Fin!O5+ABS(Captura_Fin!N5))/ABS(Captura_Fin!N5),"")) | J5: =IF(COUNT(Captura_Fin!L5,Captura_Fin!F5)<2,"",IFERROR(Captura_Fin!L5/Captura_Fin!F5,"")) | K5: =IF(COUNT(Captura_Fin!Q5)<1,"",IFERROR(IF(D5=2017,Captura_Fin!Q5/INDEX(Empresas!$I$2:$I$23,MATCH($A5,Empresas!$B$2:$B$23,0))-1,IF(COUNT(Captura_Fin!Q4)<1,"",Captura_Fin!Q5/Captura_Fin!Q4-1)),"")) | L5: =IF(COUNT(Captura_Fin!P5,Captura_Fin!H5)<2,"",IF(Captura_Fin!H5<=0,"",Captura_Fin!P5/Captura_Fin!H5)) | M5: =COUNT(E5:K5) | N5: =IF(COUNT(Captura_Fin!F5,Captura_Fin!G5,Captura_Fin!H5)<3,"",IF(ABS(Captura_Fin!F5-Captura_Fin!G5-Captura_Fin!H5)<=0.005*ABS(Captura_Fin!F5),"OK","REVISAR"))
A6: =Captura_Fin!A6 | B6: =Captura_Fin!B6 | C6: =Captura_Fin!C6 | D6: =Captura_Fin!D6 | E6: =IF(COUNT(Captura_Fin!I6,Captura_Fin!J6)<2,"",IFERROR(Captura_Fin!I6/Captura_Fin!J6,"")) | F6: =IF(COUNT(Captura_Fin!M6,Captura_Fin!L6)<2,"",IFERROR(ABS(Captura_Fin!M6)/Captura_Fin!L6,"")) | G6: =IF(COUNT(Captura_Fin!P6,Captura_Fin!F6)<2,"",IFERROR(Captura_Fin!P6/Captura_Fin!F6,"")) | H6: =IF(COUNT(Captura_Fin!G6,Captura_Fin!F6)<2,"",IFERROR(Captura_Fin!G6/Captura_Fin!F6,"")) | I6: =IF(COUNT(Captura_Fin!O6,Captura_Fin!N6)<2,"",IFERROR((Captura_Fin!O6+ABS(Captura_Fin!N6))/ABS(Captura_Fin!N6),"")) | J6: =IF(COUNT(Captura_Fin!L6,Captura_Fin!F6)<2,"",IFERROR(Captura_Fin!L6/Captura_Fin!F6,"")) | K6: =IF(COUNT(Captura_Fin!Q6)<1,"",IFERROR(IF(D6=2017,Captura_Fin!Q6/INDEX(Empresas!$I$2:$I$23,MATCH($A6,Empresas!$B$2:$B$23,0))-1,IF(COUNT(Captura_Fin!Q5)<1,"",Captura_Fin!Q6/Captura_Fin!Q5-1)),"")) | L6: =IF(COUNT(Captura_Fin!P6,Captura_Fin!H6)<2,"",IF(Captura_Fin!H6<=0,"",Captura_Fin!P6/Captura_Fin!H6)) | M6: =COUNT(E6:K6) | N6: =IF(COUNT(Captura_Fin!F6,Captura_Fin!G6,Captura_Fin!H6)<3,"",IF(ABS(Captura_Fin!F6-Captura_Fin!G6-Captura_Fin!H6)<=0.005*ABS(Captura_Fin!F6),"OK","REVISAR"))
A7: =Captura_Fin!A7 | B7: =Captura_Fin!B7 | C7: =Captura_Fin!C7 | D7: =Captura_Fin!D7 | E7: =IF(COUNT(Captura_Fin!I7,Captura_Fin!J7)<2,"",IFERROR(Captura_Fin!I7/Captura_Fin!J7,"")) | F7: =IF(COUNT(Captura_Fin!M7,Captura_Fin!L7)<2,"",IFERROR(ABS(Captura_Fin!M7)/Captura_Fin!L7,"")) | G7: =IF(COUNT(Captura_Fin!P7,Captura_Fin!F7)<2,"",IFERROR(Captura_Fin!P7/Captura_Fin!F7,"")) | H7: =IF(COUNT(Captura_Fin!G7,Captura_Fin!F7)<2,"",IFERROR(Captura_Fin!G7/Captura_Fin!F7,"")) | I7: =IF(COUNT(Captura_Fin!O7,Captura_Fin!N7)<2,"",IFERROR((Captura_Fin!O7+ABS(Captura_Fin!N7))/ABS(Captura_Fin!N7),"")) | J7: =IF(COUNT(Captura_Fin!L7,Captura_Fin!F7)<2,"",IFERROR(Captura_Fin!L7/Captura_Fin!F7,"")) | K7: =IF(COUNT(Captura_Fin!Q7)<1,"",IFERROR(IF(D7=2017,Captura_Fin!Q7/INDEX(Empresas!$I$2:$I$23,MATCH($A7,Empresas!$B$2:$B$23,0))-1,IF(COUNT(Captura_Fin!Q6)<1,"",Captura_Fin!Q7/Captura_Fin!Q6-1)),"")) | L7: =IF(COUNT(Captura_Fin!P7,Captura_Fin!H7)<2,"",IF(Captura_Fin!H7<=0,"",Captura_Fin!P7/Captura_Fin!H7)) | M7: =COUNT(E7:K7) | N7: =IF(COUNT(Captura_Fin!F7,Captura_Fin!G7,Captura_Fin!H7)<3,"",IF(ABS(Captura_Fin!F7-Captura_Fin!G7-Captura_Fin!H7)<=0.005*ABS(Captura_Fin!F7),"OK","REVISAR"))
